<?xml version = "1.0"?>
    <robot name = "WPM-2">
     <!-- material -->
    <material name = "black">
        <color rgba = "0.01 0.01 0.01 1"/>
    </material>
    <material name = "grey">
        <color rgba = "0.2 0.2 0.2 1"/>
    </material>
    <material name = "light_grey">
        <color rgba = "0.5 0.5 0.5 1"/>
    </material>
    <material name = "blue">
        <color rgba = "0.2 0.2 0.6 1"/>
    </material>
    <material name = "green">
        <color rgba = "0.2 0.6 0.2 1"/>
    </material>

    <!-- -->
    <link name = "base_link">
        <visual>
            <geometry>
                <box size = ".1 .1 .0"/>
            </geometry>
            <origin rpy = "0 0 0" xyz = "0 0 0"/>
            <material name = "grey"/>
        </visual>
        <collision>
            <geometry>
                <box size = ".1 .1 .0"/>
            </geometry>
        </collision>
        <inertial>
            <mass value = "10"/>
            <inertia ixx="1.0" ixy="0.0" ixz="0.0" iyy="1.0" iyz="0.0" izz = "1.0"/>
        </inertial>
    </link>

    <!-- ****manipulator ****-->
    <!-- mani_part_1 -->
        <link name = "wpm2_joint_1">
        <visual>
            <geometry>
                <mesh filename="package://wpm2_bringup/meshes/wpm2_joint_1.stl" scale="1 1 1"/>
            </geometry>
            <material name = "grey"/>
            <origin rpy = "1.57 0 1.57" xyz = "-0.1 -0.1 0"/>
        </visual>
    </link>
        <joint name = "base_joint1" type = "fixed">
        <parent link = "base_link"/>
        <child link = "wpm2_joint_1"/>
        <origin xyz = "0 0 0"/>
    </joint>

    <!-- mani_part_2 -->
        <link name = "wpm2_joint_2">
        <visual>
            <geometry>
                <mesh filename="package://wpm2_bringup/meshes/wpm2_joint_2.stl" scale="1 1 1"/>
            </geometry>
            <material name = "light_grey"/>
            <origin rpy = "-1.57 0 1.57" xyz = "0.135 -0.07 0.1285"/>
        </visual>
    </link>
        <joint name = "joint1_joint2" type = "revolute">
        <parent link = "wpm2_joint_1"/>
        <child link = "wpm2_joint_2"/>
        <axis xyz = "0 0 1"/>
        <origin xyz = "0 0 0.1585"/>
        <limit effort = "1000.0" lower="-3.14" upper="3.14" velocity="0.5"/>
    </joint>

    <!-- mani_part_3 -->
    <link name = "wpm2_joint_3">
        <visual>
            <geometry>
                <mesh filename="package://wpm2_bringup/meshes/wpm2_joint_3.stl" scale="1 1 1"/>
            </geometry>
            <material name = "grey"/>
            <origin rpy = "1.57 0 1.57" xyz = "-0.12 -0.08 -0.048"/>
        </visual>
    </link>
        <joint name = "joint2_joint3" type = "revolute">
        <parent link = "wpm2_joint_2"/>
        <child link = "wpm2_joint_3"/>
        <axis xyz = "0 -1 0"/>
        <origin xyz = "0 0 0.0825"/>
        <limit effort = "1000.0" lower="-3.14" upper="3.14" velocity="0.5"/>
    </joint>

    <!-- mani_part_4 -->
    <link name = "wpm2_joint_4">
        <visual>
            <geometry>
                <mesh filename="package://wpm2_bringup/meshes/wpm2_joint_4.stl" scale="1 1 1"/>
            </geometry>
            <material name = "light_grey"/>
            <origin rpy = "0 1.57 0" xyz = "-0.116 -0.057 0.122"/>
        </visual>
    </link>
        <joint name = "joint3_joint4" type = "revolute">
        <parent link = "wpm2_joint_3"/>
        <child link = "wpm2_joint_4"/>
        <axis xyz = "0 0 1"/>
        <origin xyz = "0 0 0.197"/>
        <limit effort = "1000.0" lower="-3.14" upper="3.14" velocity="0.5"/>
    </joint>

    <!-- mani_part_5 -->
    <link name = "wpm2_joint_5">
        <visual>
            <geometry>
                <mesh filename="package://wpm2_bringup/meshes/wpm2_joint_5.stl" scale="1 1 1"/>
            </geometry>
            <material name = "grey"/>
            <origin rpy = "0 -1.57 0" xyz = "0.107 -0.053 -0.033"/>
        </visual>
    </link>
        <joint name = "joint4_joint5" type = "revolute">
        <parent link = "wpm2_joint_4"/>
        <child link = "wpm2_joint_5"/>
        <axis xyz = "1 0 0"/>
        <origin xyz = "0 0 0.076"/>
        <limit effort = "1000.0" lower="-3.14" upper="3.14" velocity="0.5"/>
    </joint>

    <!-- mani_part_6 -->
    <link name = "wpm2_joint_6">
        <visual>
            <geometry>
                <mesh filename="package://wpm2_bringup/meshes/wpm2_joint_4.stl" scale="1 1 1"/>
            </geometry>
            <material name = "light_grey"/>
            <origin rpy = "0 1.57 1.57" xyz = "0.055 -0.115 0.122"/>
        </visual>
    </link>
        <joint name = "joint5_joint6" type = "revolute">
        <parent link = "wpm2_joint_5"/>
        <child link = "wpm2_joint_6"/>
        <axis xyz = "0 0 1"/>
        <origin xyz = "0 0 0.197"/>
        <limit effort = "1000.0" lower="-3.14" upper="3.14" velocity="0.5"/>
    </joint>

    <!-- mani_palm -->
    <link name = "wpm2_palm">
        <visual>
            <geometry>
                <mesh filename="package://wpm2_bringup/meshes/wpm2_palm.stl" scale="1 1 1"/>
            </geometry>
            <material name = "grey"/>
            <origin rpy = "0 -1.57 1.57" xyz = "0.0566 0.0985 -0.034"/>
        </visual>
    </link>
        <joint name = "joint6_palm" type = "revolute">
        <parent link = "wpm2_joint_6"/>
        <child link = "wpm2_palm"/>
        <axis xyz = "0 1 0"/>
        <origin xyz = "0 0 0.076"/>
        <limit effort = "1000.0" lower="-3.14" upper="3.14" velocity="0.5"/>
    </joint>

    <!-- finger -->
        <link name = "wpm2_left_finger">
        <visual>
            <geometry>
                <mesh filename="package://wpm2_bringup/meshes/wpm2_finger.stl" scale="0.001 0.001 0.001"/>
            </geometry>
                <material name = "light_grey"/>
            <origin rpy = "1.57 0 -1.57" xyz = ".021 0.005 -0.005"/>
        </visual>
    </link>
    <joint name = "wpm2_palm_finger" type = "revolute">
        <parent link = "wpm2_palm"/>
        <child link = "wpm2_left_finger"/>
        <origin xyz = "0 0.06 0.219"/>
        <axis xyz = "-1 0 0"/>
        <limit effort = "1000.0" lower="0" upper="1.0" velocity="0.5"/>
    </joint>

        <link name = "wpm2_right_finger">
        <visual>
            <geometry>
                <mesh filename="package://wpm2_bringup/meshes/wpm2_finger.stl" scale="0.001 0.001 0.001"/>
            </geometry>
                <material name = "light_grey"/>
            <origin rpy = "1.57 0 1.57" xyz = "-0.0175 -0.005 -0.005"/>
        </visual>
    </link>
    <joint name = "wpm2_palm_right_finger" type = "revolute">
        <parent link = "wpm2_palm"/>
        <child link = "wpm2_right_finger"/>
        <origin xyz = "0 -0.06 0.219"/>
        <axis xyz = "1 0 0"/>
        <limit effort = "1000.0" lower="0" upper="1.0" velocity="0.5"/>
        <mimic joint = "wpm2_palm_finger" multiplier = "1" offset = "0"/>
    </joint>
    <!-- *****************-->

    </robot>